2018-04-22 01:02:39,462 ERROR: Exception on / [GET] [in c:\users\rhlapt~1\docume~1\python~1\venvs~1\flaskw~1\lib\site-packages\flask\app.py:1560]
Traceback (most recent call last):
  File "c:\users\rhlapt~1\docume~1\python~1\venvs~1\flaskw~1\lib\site-packages\flask\app.py", line 1982, in wsgi_app
    response = self.full_dispatch_request()
  File "c:\users\rhlapt~1\docume~1\python~1\venvs~1\flaskw~1\lib\site-packages\flask\app.py", line 1614, in full_dispatch_request
    rv = self.handle_user_exception(e)
  File "c:\users\rhlapt~1\docume~1\python~1\venvs~1\flaskw~1\lib\site-packages\flask\app.py", line 1517, in handle_user_exception
    reraise(exc_type, exc_value, tb)
  File "c:\users\rhlapt~1\docume~1\python~1\venvs~1\flaskw~1\lib\site-packages\flask\_compat.py", line 33, in reraise
    raise value
  File "c:\users\rhlapt~1\docume~1\python~1\venvs~1\flaskw~1\lib\site-packages\flask\app.py", line 1612, in full_dispatch_request
    rv = self.dispatch_request()
  File "c:\users\rhlapt~1\docume~1\python~1\venvs~1\flaskw~1\lib\site-packages\flask\app.py", line 1598, in dispatch_request
    return self.view_functions[rule.endpoint](**req.view_args)
  File "C:\Users\RH Laptop\Documents\PythonFiles\PhishingProject\app\main\routes.py", line 10, in index
    page = request.args.get('page', 1, type=int)
NameError: name 'request' is not defined
2018-04-22 01:06:17,232 INFO: Phishing-Project startup [in C:\Users\RH Laptop\Documents\PythonFiles\PhishingProject\app\__init__.py:50]
2018-04-22 01:06:18,278 ERROR: Exception on / [GET] [in c:\users\rhlapt~1\docume~1\python~1\venvs~1\flaskw~1\lib\site-packages\flask\app.py:1560]
Traceback (most recent call last):
  File "c:\users\rhlapt~1\docume~1\python~1\venvs~1\flaskw~1\lib\site-packages\flask\app.py", line 1982, in wsgi_app
    response = self.full_dispatch_request()
  File "c:\users\rhlapt~1\docume~1\python~1\venvs~1\flaskw~1\lib\site-packages\flask\app.py", line 1614, in full_dispatch_request
    rv = self.handle_user_exception(e)
  File "c:\users\rhlapt~1\docume~1\python~1\venvs~1\flaskw~1\lib\site-packages\flask\app.py", line 1517, in handle_user_exception
    reraise(exc_type, exc_value, tb)
  File "c:\users\rhlapt~1\docume~1\python~1\venvs~1\flaskw~1\lib\site-packages\flask\_compat.py", line 33, in reraise
    raise value
  File "c:\users\rhlapt~1\docume~1\python~1\venvs~1\flaskw~1\lib\site-packages\flask\app.py", line 1612, in full_dispatch_request
    rv = self.dispatch_request()
  File "c:\users\rhlapt~1\docume~1\python~1\venvs~1\flaskw~1\lib\site-packages\flask\app.py", line 1598, in dispatch_request
    return self.view_functions[rule.endpoint](**req.view_args)
  File "C:\Users\RH Laptop\Documents\PythonFiles\PhishingProject\app\main\routes.py", line 11, in index
    staff = Staff.query.order_by(Staff.staffname.desc()).paginate(page, app.config['POSTS_PER_PAGE'], False)
NameError: name 'app' is not defined
2018-04-22 01:06:19,481 ERROR: Exception on / [GET] [in c:\users\rhlapt~1\docume~1\python~1\venvs~1\flaskw~1\lib\site-packages\flask\app.py:1560]
Traceback (most recent call last):
  File "c:\users\rhlapt~1\docume~1\python~1\venvs~1\flaskw~1\lib\site-packages\flask\app.py", line 1982, in wsgi_app
    response = self.full_dispatch_request()
  File "c:\users\rhlapt~1\docume~1\python~1\venvs~1\flaskw~1\lib\site-packages\flask\app.py", line 1614, in full_dispatch_request
    rv = self.handle_user_exception(e)
  File "c:\users\rhlapt~1\docume~1\python~1\venvs~1\flaskw~1\lib\site-packages\flask\app.py", line 1517, in handle_user_exception
    reraise(exc_type, exc_value, tb)
  File "c:\users\rhlapt~1\docume~1\python~1\venvs~1\flaskw~1\lib\site-packages\flask\_compat.py", line 33, in reraise
    raise value
  File "c:\users\rhlapt~1\docume~1\python~1\venvs~1\flaskw~1\lib\site-packages\flask\app.py", line 1612, in full_dispatch_request
    rv = self.dispatch_request()
  File "c:\users\rhlapt~1\docume~1\python~1\venvs~1\flaskw~1\lib\site-packages\flask\app.py", line 1598, in dispatch_request
    return self.view_functions[rule.endpoint](**req.view_args)
  File "C:\Users\RH Laptop\Documents\PythonFiles\PhishingProject\app\main\routes.py", line 11, in index
    staff = Staff.query.order_by(Staff.staffname.desc()).paginate(page, app.config['POSTS_PER_PAGE'], False)
NameError: name 'app' is not defined
2018-04-22 01:09:12,500 INFO: Phishing-Project startup [in C:\Users\RH Laptop\Documents\PythonFiles\PhishingProject\app\__init__.py:50]
2018-04-22 01:09:13,914 ERROR: Exception on / [GET] [in c:\users\rhlapt~1\docume~1\python~1\venvs~1\flaskw~1\lib\site-packages\flask\app.py:1560]
Traceback (most recent call last):
  File "c:\users\rhlapt~1\docume~1\python~1\venvs~1\flaskw~1\lib\site-packages\flask\app.py", line 1982, in wsgi_app
    response = self.full_dispatch_request()
  File "c:\users\rhlapt~1\docume~1\python~1\venvs~1\flaskw~1\lib\site-packages\flask\app.py", line 1614, in full_dispatch_request
    rv = self.handle_user_exception(e)
  File "c:\users\rhlapt~1\docume~1\python~1\venvs~1\flaskw~1\lib\site-packages\flask\app.py", line 1517, in handle_user_exception
    reraise(exc_type, exc_value, tb)
  File "c:\users\rhlapt~1\docume~1\python~1\venvs~1\flaskw~1\lib\site-packages\flask\_compat.py", line 33, in reraise
    raise value
  File "c:\users\rhlapt~1\docume~1\python~1\venvs~1\flaskw~1\lib\site-packages\flask\app.py", line 1612, in full_dispatch_request
    rv = self.dispatch_request()
  File "c:\users\rhlapt~1\docume~1\python~1\venvs~1\flaskw~1\lib\site-packages\flask\app.py", line 1598, in dispatch_request
    return self.view_functions[rule.endpoint](**req.view_args)
  File "C:\Users\RH Laptop\Documents\PythonFiles\PhishingProject\app\main\routes.py", line 11, in index
    staff = Staff.query.order_by(Staff.staffname.desc()).paginate(page, app.config['POSTS_PER_PAGE'], False)
NameError: name 'app' is not defined
2018-04-22 01:12:33,139 INFO: Phishing-Project startup [in C:\Users\RH Laptop\Documents\PythonFiles\PhishingProject\app\__init__.py:50]
2018-04-22 01:12:34,419 ERROR: Exception on / [GET] [in c:\users\rhlapt~1\docume~1\python~1\venvs~1\flaskw~1\lib\site-packages\flask\app.py:1560]
Traceback (most recent call last):
  File "c:\users\rhlapt~1\docume~1\python~1\venvs~1\flaskw~1\lib\site-packages\flask\app.py", line 1982, in wsgi_app
    response = self.full_dispatch_request()
  File "c:\users\rhlapt~1\docume~1\python~1\venvs~1\flaskw~1\lib\site-packages\flask\app.py", line 1614, in full_dispatch_request
    rv = self.handle_user_exception(e)
  File "c:\users\rhlapt~1\docume~1\python~1\venvs~1\flaskw~1\lib\site-packages\flask\app.py", line 1517, in handle_user_exception
    reraise(exc_type, exc_value, tb)
  File "c:\users\rhlapt~1\docume~1\python~1\venvs~1\flaskw~1\lib\site-packages\flask\_compat.py", line 33, in reraise
    raise value
  File "c:\users\rhlapt~1\docume~1\python~1\venvs~1\flaskw~1\lib\site-packages\flask\app.py", line 1612, in full_dispatch_request
    rv = self.dispatch_request()
  File "c:\users\rhlapt~1\docume~1\python~1\venvs~1\flaskw~1\lib\site-packages\flask\app.py", line 1598, in dispatch_request
    return self.view_functions[rule.endpoint](**req.view_args)
  File "C:\Users\RH Laptop\Documents\PythonFiles\PhishingProject\app\main\routes.py", line 28, in index
    return render_template('index.html', title='Dashboard', form=form, staff=staff.items, next_url=next_url, prev_url=prev_url)
AttributeError: 'list' object has no attribute 'items'
2018-04-22 01:12:36,904 ERROR: Exception on / [GET] [in c:\users\rhlapt~1\docume~1\python~1\venvs~1\flaskw~1\lib\site-packages\flask\app.py:1560]
Traceback (most recent call last):
  File "c:\users\rhlapt~1\docume~1\python~1\venvs~1\flaskw~1\lib\site-packages\flask\app.py", line 1982, in wsgi_app
    response = self.full_dispatch_request()
  File "c:\users\rhlapt~1\docume~1\python~1\venvs~1\flaskw~1\lib\site-packages\flask\app.py", line 1614, in full_dispatch_request
    rv = self.handle_user_exception(e)
  File "c:\users\rhlapt~1\docume~1\python~1\venvs~1\flaskw~1\lib\site-packages\flask\app.py", line 1517, in handle_user_exception
    reraise(exc_type, exc_value, tb)
  File "c:\users\rhlapt~1\docume~1\python~1\venvs~1\flaskw~1\lib\site-packages\flask\_compat.py", line 33, in reraise
    raise value
  File "c:\users\rhlapt~1\docume~1\python~1\venvs~1\flaskw~1\lib\site-packages\flask\app.py", line 1612, in full_dispatch_request
    rv = self.dispatch_request()
  File "c:\users\rhlapt~1\docume~1\python~1\venvs~1\flaskw~1\lib\site-packages\flask\app.py", line 1598, in dispatch_request
    return self.view_functions[rule.endpoint](**req.view_args)
  File "C:\Users\RH Laptop\Documents\PythonFiles\PhishingProject\app\main\routes.py", line 28, in index
    return render_template('index.html', title='Dashboard', form=form, staff=staff.items, next_url=next_url, prev_url=prev_url)
AttributeError: 'list' object has no attribute 'items'
2018-04-22 01:18:20,208 INFO: Phishing-Project startup [in C:\Users\RH Laptop\Documents\PythonFiles\PhishingProject\app\__init__.py:50]
