2018-04-19 13:32:03,373 ERROR: Exception on / [GET] [in c:\users\rhlapt~1\docume~1\python~1\venvs~1\flaskw~1\lib\site-packages\flask\app.py:1560]
Traceback (most recent call last):
  File "c:\users\rhlapt~1\docume~1\python~1\venvs~1\flaskw~1\lib\site-packages\flask\app.py", line 1982, in wsgi_app
    response = self.full_dispatch_request()
  File "c:\users\rhlapt~1\docume~1\python~1\venvs~1\flaskw~1\lib\site-packages\flask\app.py", line 1614, in full_dispatch_request
    rv = self.handle_user_exception(e)
  File "c:\users\rhlapt~1\docume~1\python~1\venvs~1\flaskw~1\lib\site-packages\flask\app.py", line 1517, in handle_user_exception
    reraise(exc_type, exc_value, tb)
  File "c:\users\rhlapt~1\docume~1\python~1\venvs~1\flaskw~1\lib\site-packages\flask\_compat.py", line 33, in reraise
    raise value
  File "c:\users\rhlapt~1\docume~1\python~1\venvs~1\flaskw~1\lib\site-packages\flask\app.py", line 1612, in full_dispatch_request
    rv = self.dispatch_request()
  File "c:\users\rhlapt~1\docume~1\python~1\venvs~1\flaskw~1\lib\site-packages\flask\app.py", line 1598, in dispatch_request
    return self.view_functions[rule.endpoint](**req.view_args)
  File "C:\Users\RH Laptop\Documents\PythonFiles\PhishingProject\app\main\routes.py", line 10, in index
    return render_template('index.html', title='Home')
  File "c:\users\rhlapt~1\docume~1\python~1\venvs~1\flaskw~1\lib\site-packages\flask\templating.py", line 134, in render_template
    context, ctx.app)
  File "c:\users\rhlapt~1\docume~1\python~1\venvs~1\flaskw~1\lib\site-packages\flask\templating.py", line 116, in _render
    rv = template.render(context)
  File "c:\users\rhlapt~1\docume~1\python~1\venvs~1\flaskw~1\lib\site-packages\jinja2\asyncsupport.py", line 76, in render
    return original_render(self, *args, **kwargs)
  File "c:\users\rhlapt~1\docume~1\python~1\venvs~1\flaskw~1\lib\site-packages\jinja2\environment.py", line 1008, in render
    return self.environment.handle_exception(exc_info, True)
  File "c:\users\rhlapt~1\docume~1\python~1\venvs~1\flaskw~1\lib\site-packages\jinja2\environment.py", line 780, in handle_exception
    reraise(exc_type, exc_value, tb)
  File "c:\users\rhlapt~1\docume~1\python~1\venvs~1\flaskw~1\lib\site-packages\jinja2\_compat.py", line 37, in reraise
    raise value.with_traceback(tb)
  File "C:\Users\RH Laptop\Documents\PythonFiles\PhishingProject\app\templates\index.html", line 1, in top-level template code
    {% extends "base.html" %}
  File "C:\Users\RH Laptop\Documents\PythonFiles\PhishingProject\app\templates\base.html", line 13, in top-level template code
    <a href="{{ url_for('main/addusers') }}">Add Users</a>
  File "c:\users\rhlapt~1\docume~1\python~1\venvs~1\flaskw~1\lib\site-packages\flask\helpers.py", line 333, in url_for
    return appctx.app.handle_url_build_error(error, endpoint, values)
  File "c:\users\rhlapt~1\docume~1\python~1\venvs~1\flaskw~1\lib\site-packages\flask\app.py", line 1805, in handle_url_build_error
    reraise(exc_type, exc_value, tb)
  File "c:\users\rhlapt~1\docume~1\python~1\venvs~1\flaskw~1\lib\site-packages\flask\_compat.py", line 33, in reraise
    raise value
  File "c:\users\rhlapt~1\docume~1\python~1\venvs~1\flaskw~1\lib\site-packages\flask\helpers.py", line 323, in url_for
    force_external=external)
  File "c:\users\rhlapt~1\docume~1\python~1\venvs~1\flaskw~1\lib\site-packages\werkzeug\routing.py", line 1776, in build
    raise BuildError(endpoint, values, method, self)
werkzeug.routing.BuildError: Could not build url for endpoint 'main/addusers'. Did you mean 'main.addusers' instead?
2018-04-19 13:32:07,325 ERROR: Exception on /addusers [GET] [in c:\users\rhlapt~1\docume~1\python~1\venvs~1\flaskw~1\lib\site-packages\flask\app.py:1560]
Traceback (most recent call last):
  File "c:\users\rhlapt~1\docume~1\python~1\venvs~1\flaskw~1\lib\site-packages\flask\app.py", line 1982, in wsgi_app
    response = self.full_dispatch_request()
  File "c:\users\rhlapt~1\docume~1\python~1\venvs~1\flaskw~1\lib\site-packages\flask\app.py", line 1614, in full_dispatch_request
    rv = self.handle_user_exception(e)
  File "c:\users\rhlapt~1\docume~1\python~1\venvs~1\flaskw~1\lib\site-packages\flask\app.py", line 1517, in handle_user_exception
    reraise(exc_type, exc_value, tb)
  File "c:\users\rhlapt~1\docume~1\python~1\venvs~1\flaskw~1\lib\site-packages\flask\_compat.py", line 33, in reraise
    raise value
  File "c:\users\rhlapt~1\docume~1\python~1\venvs~1\flaskw~1\lib\site-packages\flask\app.py", line 1612, in full_dispatch_request
    rv = self.dispatch_request()
  File "c:\users\rhlapt~1\docume~1\python~1\venvs~1\flaskw~1\lib\site-packages\flask\app.py", line 1598, in dispatch_request
    return self.view_functions[rule.endpoint](**req.view_args)
  File "C:\Users\RH Laptop\Documents\PythonFiles\PhishingProject\app\main\routes.py", line 21, in addusers
    return render_template('main/addusers.html', title='Add Users', form=form)
  File "c:\users\rhlapt~1\docume~1\python~1\venvs~1\flaskw~1\lib\site-packages\flask\templating.py", line 134, in render_template
    context, ctx.app)
  File "c:\users\rhlapt~1\docume~1\python~1\venvs~1\flaskw~1\lib\site-packages\flask\templating.py", line 116, in _render
    rv = template.render(context)
  File "c:\users\rhlapt~1\docume~1\python~1\venvs~1\flaskw~1\lib\site-packages\jinja2\asyncsupport.py", line 76, in render
    return original_render(self, *args, **kwargs)
  File "c:\users\rhlapt~1\docume~1\python~1\venvs~1\flaskw~1\lib\site-packages\jinja2\environment.py", line 1008, in render
    return self.environment.handle_exception(exc_info, True)
  File "c:\users\rhlapt~1\docume~1\python~1\venvs~1\flaskw~1\lib\site-packages\jinja2\environment.py", line 780, in handle_exception
    reraise(exc_type, exc_value, tb)
  File "c:\users\rhlapt~1\docume~1\python~1\venvs~1\flaskw~1\lib\site-packages\jinja2\_compat.py", line 37, in reraise
    raise value.with_traceback(tb)
  File "C:\Users\RH Laptop\Documents\PythonFiles\PhishingProject\app\templates\main\addusers.html", line 1, in top-level template code
    {% extends "base.html" %}
  File "C:\Users\RH Laptop\Documents\PythonFiles\PhishingProject\app\templates\base.html", line 13, in top-level template code
    <a href="{{ url_for('main/addusers') }}">Add Users</a>
  File "c:\users\rhlapt~1\docume~1\python~1\venvs~1\flaskw~1\lib\site-packages\flask\helpers.py", line 333, in url_for
    return appctx.app.handle_url_build_error(error, endpoint, values)
  File "c:\users\rhlapt~1\docume~1\python~1\venvs~1\flaskw~1\lib\site-packages\flask\app.py", line 1805, in handle_url_build_error
    reraise(exc_type, exc_value, tb)
  File "c:\users\rhlapt~1\docume~1\python~1\venvs~1\flaskw~1\lib\site-packages\flask\_compat.py", line 33, in reraise
    raise value
  File "c:\users\rhlapt~1\docume~1\python~1\venvs~1\flaskw~1\lib\site-packages\flask\helpers.py", line 323, in url_for
    force_external=external)
  File "c:\users\rhlapt~1\docume~1\python~1\venvs~1\flaskw~1\lib\site-packages\werkzeug\routing.py", line 1776, in build
    raise BuildError(endpoint, values, method, self)
werkzeug.routing.BuildError: Could not build url for endpoint 'main/addusers'. Did you mean 'main.addusers' instead?
2018-04-19 13:35:04,944 INFO: PhishingProject startup [in C:\Users\RH Laptop\Documents\PythonFiles\PhishingProject\app\__init__.py:50]
