2018-04-22 01:58:07,828 ERROR: Exception on / [POST] [in c:\users\rhlapt~1\docume~1\python~1\venvs~1\flaskw~1\lib\site-packages\flask\app.py:1560]
Traceback (most recent call last):
  File "c:\users\rhlapt~1\docume~1\python~1\venvs~1\flaskw~1\lib\site-packages\flask\app.py", line 1982, in wsgi_app
    response = self.full_dispatch_request()
  File "c:\users\rhlapt~1\docume~1\python~1\venvs~1\flaskw~1\lib\site-packages\flask\app.py", line 1614, in full_dispatch_request
    rv = self.handle_user_exception(e)
  File "c:\users\rhlapt~1\docume~1\python~1\venvs~1\flaskw~1\lib\site-packages\flask\app.py", line 1517, in handle_user_exception
    reraise(exc_type, exc_value, tb)
  File "c:\users\rhlapt~1\docume~1\python~1\venvs~1\flaskw~1\lib\site-packages\flask\_compat.py", line 33, in reraise
    raise value
  File "c:\users\rhlapt~1\docume~1\python~1\venvs~1\flaskw~1\lib\site-packages\flask\app.py", line 1612, in full_dispatch_request
    rv = self.dispatch_request()
  File "c:\users\rhlapt~1\docume~1\python~1\venvs~1\flaskw~1\lib\site-packages\flask\app.py", line 1598, in dispatch_request
    return self.view_functions[rule.endpoint](**req.view_args)
  File "C:\Users\RH Laptop\Documents\PythonFiles\PhishingProject\app\main\routes.py", line 27, in index
    return redirect(url_for('index'))
  File "c:\users\rhlapt~1\docume~1\python~1\venvs~1\flaskw~1\lib\site-packages\flask\helpers.py", line 333, in url_for
    return appctx.app.handle_url_build_error(error, endpoint, values)
  File "c:\users\rhlapt~1\docume~1\python~1\venvs~1\flaskw~1\lib\site-packages\flask\app.py", line 1805, in handle_url_build_error
    reraise(exc_type, exc_value, tb)
  File "c:\users\rhlapt~1\docume~1\python~1\venvs~1\flaskw~1\lib\site-packages\flask\_compat.py", line 33, in reraise
    raise value
  File "c:\users\rhlapt~1\docume~1\python~1\venvs~1\flaskw~1\lib\site-packages\flask\helpers.py", line 323, in url_for
    force_external=external)
  File "c:\users\rhlapt~1\docume~1\python~1\venvs~1\flaskw~1\lib\site-packages\werkzeug\routing.py", line 1776, in build
    raise BuildError(endpoint, values, method, self)
werkzeug.routing.BuildError: Could not build url for endpoint 'index'. Did you mean 'main.index' instead?
2018-04-22 01:58:37,982 INFO: Phishing-Project startup [in C:\Users\RH Laptop\Documents\PythonFiles\PhishingProject\app\__init__.py:50]
2018-04-22 01:58:56,173 ERROR: Exception on / [POST] [in c:\users\rhlapt~1\docume~1\python~1\venvs~1\flaskw~1\lib\site-packages\flask\app.py:1560]
Traceback (most recent call last):
  File "c:\users\rhlapt~1\docume~1\python~1\venvs~1\flaskw~1\lib\site-packages\flask\app.py", line 1982, in wsgi_app
    response = self.full_dispatch_request()
  File "c:\users\rhlapt~1\docume~1\python~1\venvs~1\flaskw~1\lib\site-packages\flask\app.py", line 1614, in full_dispatch_request
    rv = self.handle_user_exception(e)
  File "c:\users\rhlapt~1\docume~1\python~1\venvs~1\flaskw~1\lib\site-packages\flask\app.py", line 1517, in handle_user_exception
    reraise(exc_type, exc_value, tb)
  File "c:\users\rhlapt~1\docume~1\python~1\venvs~1\flaskw~1\lib\site-packages\flask\_compat.py", line 33, in reraise
    raise value
  File "c:\users\rhlapt~1\docume~1\python~1\venvs~1\flaskw~1\lib\site-packages\flask\app.py", line 1612, in full_dispatch_request
    rv = self.dispatch_request()
  File "c:\users\rhlapt~1\docume~1\python~1\venvs~1\flaskw~1\lib\site-packages\flask\app.py", line 1598, in dispatch_request
    return self.view_functions[rule.endpoint](**req.view_args)
  File "C:\Users\RH Laptop\Documents\PythonFiles\PhishingProject\app\main\routes.py", line 28, in index
    return redirect(url_for('index'))
  File "c:\users\rhlapt~1\docume~1\python~1\venvs~1\flaskw~1\lib\site-packages\flask\helpers.py", line 333, in url_for
    return appctx.app.handle_url_build_error(error, endpoint, values)
  File "c:\users\rhlapt~1\docume~1\python~1\venvs~1\flaskw~1\lib\site-packages\flask\app.py", line 1805, in handle_url_build_error
    reraise(exc_type, exc_value, tb)
  File "c:\users\rhlapt~1\docume~1\python~1\venvs~1\flaskw~1\lib\site-packages\flask\_compat.py", line 33, in reraise
    raise value
  File "c:\users\rhlapt~1\docume~1\python~1\venvs~1\flaskw~1\lib\site-packages\flask\helpers.py", line 323, in url_for
    force_external=external)
  File "c:\users\rhlapt~1\docume~1\python~1\venvs~1\flaskw~1\lib\site-packages\werkzeug\routing.py", line 1776, in build
    raise BuildError(endpoint, values, method, self)
werkzeug.routing.BuildError: Could not build url for endpoint 'index'. Did you mean 'main.index' instead?
2018-04-22 02:01:38,189 INFO: Phishing-Project startup [in C:\Users\RH Laptop\Documents\PythonFiles\PhishingProject\app\__init__.py:50]
2018-04-22 02:01:42,653 ERROR: Exception on / [GET] [in c:\users\rhlapt~1\docume~1\python~1\venvs~1\flaskw~1\lib\site-packages\flask\app.py:1560]
Traceback (most recent call last):
  File "c:\users\rhlapt~1\docume~1\python~1\venvs~1\flaskw~1\lib\site-packages\flask\app.py", line 1982, in wsgi_app
    response = self.full_dispatch_request()
  File "c:\users\rhlapt~1\docume~1\python~1\venvs~1\flaskw~1\lib\site-packages\flask\app.py", line 1614, in full_dispatch_request
    rv = self.handle_user_exception(e)
  File "c:\users\rhlapt~1\docume~1\python~1\venvs~1\flaskw~1\lib\site-packages\flask\app.py", line 1517, in handle_user_exception
    reraise(exc_type, exc_value, tb)
  File "c:\users\rhlapt~1\docume~1\python~1\venvs~1\flaskw~1\lib\site-packages\flask\_compat.py", line 33, in reraise
    raise value
  File "c:\users\rhlapt~1\docume~1\python~1\venvs~1\flaskw~1\lib\site-packages\flask\app.py", line 1612, in full_dispatch_request
    rv = self.dispatch_request()
  File "c:\users\rhlapt~1\docume~1\python~1\venvs~1\flaskw~1\lib\site-packages\flask\app.py", line 1598, in dispatch_request
    return self.view_functions[rule.endpoint](**req.view_args)
  File "C:\Users\RH Laptop\Documents\PythonFiles\PhishingProject\app\main\routes.py", line 20, in index
    next_url = url_for('index', page=staff.next_num)
  File "c:\users\rhlapt~1\docume~1\python~1\venvs~1\flaskw~1\lib\site-packages\flask\helpers.py", line 333, in url_for
    return appctx.app.handle_url_build_error(error, endpoint, values)
  File "c:\users\rhlapt~1\docume~1\python~1\venvs~1\flaskw~1\lib\site-packages\flask\app.py", line 1805, in handle_url_build_error
    reraise(exc_type, exc_value, tb)
  File "c:\users\rhlapt~1\docume~1\python~1\venvs~1\flaskw~1\lib\site-packages\flask\_compat.py", line 33, in reraise
    raise value
  File "c:\users\rhlapt~1\docume~1\python~1\venvs~1\flaskw~1\lib\site-packages\flask\helpers.py", line 323, in url_for
    force_external=external)
  File "c:\users\rhlapt~1\docume~1\python~1\venvs~1\flaskw~1\lib\site-packages\werkzeug\routing.py", line 1776, in build
    raise BuildError(endpoint, values, method, self)
werkzeug.routing.BuildError: Could not build url for endpoint 'index' with values ['page']. Did you mean 'main.index' instead?
2018-04-22 02:02:43,828 INFO: Phishing-Project startup [in C:\Users\RH Laptop\Documents\PythonFiles\PhishingProject\app\__init__.py:50]
2018-04-22 02:03:50,167 INFO: Phishing-Project startup [in C:\Users\RH Laptop\Documents\PythonFiles\PhishingProject\app\__init__.py:50]
2018-04-22 02:04:27,355 INFO: Phishing-Project startup [in C:\Users\RH Laptop\Documents\PythonFiles\PhishingProject\app\__init__.py:50]
2018-04-22 02:05:01,447 INFO: Phishing-Project startup [in C:\Users\RH Laptop\Documents\PythonFiles\PhishingProject\app\__init__.py:50]
2018-04-22 02:07:01,555 INFO: Phishing-Project startup [in C:\Users\RH Laptop\Documents\PythonFiles\PhishingProject\app\__init__.py:50]
2018-04-22 02:07:34,123 INFO: Phishing-Project startup [in C:\Users\RH Laptop\Documents\PythonFiles\PhishingProject\app\__init__.py:50]
2018-04-22 14:11:44,305 INFO: Phishing-Project startup [in C:\Users\RH Laptop\Documents\PythonFiles\PhishingProject\app\__init__.py:50]
2018-04-22 17:22:36,258 INFO: Phishing-Project startup [in C:\Users\RH Laptop\Documents\PythonFiles\PhishingProject\app\__init__.py:50]
2018-04-23 09:55:05,135 INFO: Phishing-Project startup [in C:\Users\RH Laptop\Documents\PythonFiles\PhishingProject\app\__init__.py:50]
2018-04-23 10:03:20,215 INFO: Phishing-Project startup [in C:\Users\RH Laptop\Documents\PythonFiles\PhishingProject\app\__init__.py:50]
2018-04-23 10:03:29,470 ERROR: Exception on /staff/1 [GET] [in c:\users\rhlapt~1\docume~1\python~1\venvs~1\flaskw~1\lib\site-packages\flask\app.py:1560]
Traceback (most recent call last):
  File "c:\users\rhlapt~1\docume~1\python~1\venvs~1\flaskw~1\lib\site-packages\flask\app.py", line 1982, in wsgi_app
    response = self.full_dispatch_request()
  File "c:\users\rhlapt~1\docume~1\python~1\venvs~1\flaskw~1\lib\site-packages\flask\app.py", line 1614, in full_dispatch_request
    rv = self.handle_user_exception(e)
  File "c:\users\rhlapt~1\docume~1\python~1\venvs~1\flaskw~1\lib\site-packages\flask\app.py", line 1517, in handle_user_exception
    reraise(exc_type, exc_value, tb)
  File "c:\users\rhlapt~1\docume~1\python~1\venvs~1\flaskw~1\lib\site-packages\flask\_compat.py", line 33, in reraise
    raise value
  File "c:\users\rhlapt~1\docume~1\python~1\venvs~1\flaskw~1\lib\site-packages\flask\app.py", line 1612, in full_dispatch_request
    rv = self.dispatch_request()
  File "c:\users\rhlapt~1\docume~1\python~1\venvs~1\flaskw~1\lib\site-packages\flask\app.py", line 1598, in dispatch_request
    return self.view_functions[rule.endpoint](**req.view_args)
TypeError: staff() got an unexpected keyword argument 'staffid'
2018-04-23 10:03:55,461 INFO: Phishing-Project startup [in C:\Users\RH Laptop\Documents\PythonFiles\PhishingProject\app\__init__.py:50]
2018-04-23 10:04:56,157 INFO: Phishing-Project startup [in C:\Users\RH Laptop\Documents\PythonFiles\PhishingProject\app\__init__.py:50]
